using System;
using System.Collections.Generic;
using System.Diagnostics;
using System.Threading.Tasks;
using FluentAssertions.Extensions;
using Xunit;
using Xunit.Sdk;

namespace FluentAssertions.Specs
{
    public class AsyncFunctionExceptionAssertionSpecs
    {
        [Fact]
        public void When_getting_the_subject_it_should_remain_unchanged()
        {
            // Arrange
            Func<Task> subject = () => Task.FromResult(42);

            // Act
            Action action = () => subject.Should().Subject.As<object>().Should().BeSameAs(subject);

            // Assert
            action.Should().NotThrow("the Subject should remain the same");
        }

        [Fact]
        public void When_method_throws_an_empty_AggregateException_it_should_fail()
        {
            // Arrange
            Func<Task> act = () => throw new AggregateException();

            // Act
            Action act2 = () => act.Should().NotThrow();

            // Assert
            act2.Should().Throw<XunitException>();
        }

        [Fact]
        public void When_subject_is_null_when_expecting_an_exception_it_should_throw()
        {
            // Arrange
            Func<Task> action = null;

            // Act
            Func<Task> testAction = () => action.Should().ThrowAsync<ArgumentException>(
                "because we want to test the failure {0}", "message");

            // Assert
            testAction.Should().Throw<XunitException>()
                .WithMessage("*because we want to test the failure message*found <null>*");
        }

        [Fact]
        public void When_subject_is_null_when_not_expecting_a_generic_exception_it_should_throw()
        {
            // Arrange
            Func<Task> action = null;

            // Act
            Func<Task> testAction = () => action.Should().NotThrowAsync<ArgumentException>(
                "because we want to test the failure {0}", "message");

            // Assert
            testAction.Should().Throw<XunitException>()
                .WithMessage("*because we want to test the failure message*found <null>*");
        }

        [Fact]
        public void When_subject_is_null_when_not_expecting_an_exception_it_should_throw()
        {
            // Arrange
            Func<Task> action = null;

            // Act
            Func<Task> testAction = () => action.Should().NotThrowAsync(
                "because we want to test the failure {0}", "message");

            // Assert
            testAction.Should().Throw<XunitException>()
                .WithMessage("*because we want to test the failure message*found <null>*");
        }

        [Fact]
        public async Task When_async_method_throws_an_empty_AggregateException_it_should_fail()
        {
            // Arrange
            Func<Task> act = () => throw new AggregateException();

            // Act
            Func<Task> act2 = () => act.Should().NotThrowAsync();

            // Assert
            await act2.Should().ThrowAsync<XunitException>();
        }

        [Fact]
        public async Task When_async_method_throws_a_nested_AggregateException_it_should_provide_the_message()
        {
            // Arrange
            Func<Task> act = () => throw new AggregateException(new ArgumentException("That was wrong."));

            // Act & Assert
            await act.Should().ThrowAsync<ArgumentException>().WithMessage("That was wrong.");
        }

        [Fact]
        public async Task When_async_method_throws_a_flat_AggregateException_it_should_provide_the_message()
        {
            // Arrange
            Func<Task> act = () => throw new AggregateException("That was wrong as well.");

            // Act & Assert
            await act.Should().ThrowAsync<AggregateException>().WithMessage("That was wrong as well.");
        }

#pragma warning disable xUnit1026 // Theory methods should use all of their parameters
        [Theory]
        [MemberData(nameof(AggregateExceptionTestData))]
        public void When_the_expected_exception_is_wrapped_it_should_succeed<T>(Func<Task> action, T _)
            where T : Exception
        {
            // Act/Assert
            action.Should().Throw<T>();
        }

        [Theory]
        [MemberData(nameof(AggregateExceptionTestData))]
        public async Task When_the_expected_exception_is_wrapped_async_it_should_succeed<T>(Func<Task> action, T _)
            where T : Exception
        {
            // Act/Assert
            await action.Should().ThrowAsync<T>();
        }

        [Theory]
        [MemberData(nameof(AggregateExceptionTestData))]
        public void When_the_expected_exception_is_not_wrapped_it_should_fail<T>(Func<Task> action, T _)
            where T : Exception
        {
            // Act
            Action act2 = () => action.Should().NotThrow<T>();

            // Assert
            act2.Should().Throw<XunitException>();
        }

        [Theory]
        [MemberData(nameof(AggregateExceptionTestData))]
        public async Task When_the_expected_exception_is_not_wrapped_async_it_should_fail<T>(Func<Task> action, T _)
            where T : Exception
        {
            // Act
            Func<Task> act2 = () => action.Should().NotThrowAsync<T>();

            // Assert
            await act2.Should().ThrowAsync<XunitException>();
        }
#pragma warning restore xUnit1026 // Theory methods should use all of their parameters

        public static IEnumerable<object[]> AggregateExceptionTestData()
        {
            var tasks = new Func<Task>[]
            {
                AggregateExceptionWithLeftNestedException,
                AggregateExceptionWithRightNestedException
            };

            var types = new Exception[]
            {
                new AggregateException(),
                new ArgumentNullException(),
                new InvalidOperationException()
            };

            foreach (var task in tasks)
            {
                foreach (var type in types)
                {
                    yield return new object[] { task, type };
                }
            }

            yield return new object[] { (Func<Task>)EmptyAggregateException, new AggregateException() };
        }

        private static Task AggregateExceptionWithLeftNestedException()
        {
            var ex1 = new AggregateException(new InvalidOperationException());
            var ex2 = new ArgumentNullException();
            var wrapped = new AggregateException(ex1, ex2);

            return FromException(wrapped);
        }

        private static Task AggregateExceptionWithRightNestedException()
        {
            var ex1 = new ArgumentNullException();
            var ex2 = new AggregateException(new InvalidOperationException());
            var wrapped = new AggregateException(ex1, ex2);

            return FromException(wrapped);
        }

        private static Task EmptyAggregateException()
        {
            return FromException(new AggregateException());
        }

        private static Task FromException(AggregateException exception)
        {
#if NET45
            var tcs = new TaskCompletionSource<int>();
            tcs.SetException(exception);
            return tcs.Task;
#else
            return Task.FromException(exception);
#endif
        }

        [Fact]
        public void When_subject_throws_subclass_of_expected_exact_exception_it_should_fail()
        {
            // Arrange
            var asyncObject = new AsyncClass();

            // Act
            Action action = () => asyncObject
                .Awaiting(x => x.ThrowAsync<ArgumentNullException>())
                .Should().ThrowExactly<ArgumentException>("because {0} should do that", "IFoo.Do");

            // Assert
            action.Should().Throw<XunitException>()
                .WithMessage("Expected type to be System.ArgumentException because IFoo.Do should do that, but found System.ArgumentNullException.");
        }

#if NETCOREAPP2_1 || NETCOREAPP3_0
        [Fact]
        public void When_subject_ValueTask_throws_subclass_of_expected_exact_exception_it_should_fail()
        {
            //-----------------------------------------------------------------------------------------------------------
            // Arrange
            //-----------------------------------------------------------------------------------------------------------
            var asyncObject = new AsyncClass();

            //-----------------------------------------------------------------------------------------------------------
            // Act
            //-----------------------------------------------------------------------------------------------------------
            Action action = () => asyncObject
                .Awaiting(x => x.ThrowAsyncValueTask<ArgumentNullException>())
                .Should().ThrowExactly<ArgumentException>("because {0} should do that", "IFoo.Do");

            //-----------------------------------------------------------------------------------------------------------
            // Assert
            //-----------------------------------------------------------------------------------------------------------
            action.Should().Throw<XunitException>()
                .WithMessage("Expected type to be System.ArgumentException because IFoo.Do should do that, but found System.ArgumentNullException.");
        }
#endif

        [Fact]
        public void When_subject_throws_aggregate_exception_and_not_expected_exact_exception_it_should_fail()
        {
            // Arrange
            var asyncObject = new AsyncClass();

            // Act
            Action action = () => asyncObject
                .Awaiting(x => x.ThrowAggregateExceptionAsync<ArgumentException>())
                .Should().ThrowExactly<ArgumentException>("because {0} should do that", "IFoo.Do");

            // Assert
            action.Should().Throw<XunitException>()
                .WithMessage("Expected type to be System.ArgumentException because IFoo.Do should do that, but found System.AggregateException.");
        }

#if NETCOREAPP2_1 || NETCOREAPP3_0
        [Fact]
        public void When_subject_throws_aggregate_exception_and_not_expected_exact_exception_through_ValueTask_it_should_fail()
        {
            //-----------------------------------------------------------------------------------------------------------
            // Arrange
            //-----------------------------------------------------------------------------------------------------------
            var asyncObject = new AsyncClass();

            //-----------------------------------------------------------------------------------------------------------
            // Act
            //-----------------------------------------------------------------------------------------------------------
            Action action = () => asyncObject
                .Awaiting(x => x.ThrowAggregateExceptionAsyncValueTask<ArgumentException>())
                .Should().ThrowExactly<ArgumentException>("because {0} should do that", "IFoo.Do");

            //-----------------------------------------------------------------------------------------------------------
            // Assert
            //-----------------------------------------------------------------------------------------------------------
            action.Should().Throw<XunitException>()
                .WithMessage("Expected type to be System.ArgumentException because IFoo.Do should do that, but found System.AggregateException.");
        }
#endif

        [Fact]
        public void When_subject_throws_the_expected_exact_exception_it_should_succeed()
        {
            // Arrange
            var asyncObject = new AsyncClass();

            // Act / Assert
            asyncObject
                .Awaiting(x => x.ThrowAsync<ArgumentNullException>())
                .Should().ThrowExactly<ArgumentNullException>();
        }

#if NETCOREAPP2_1 || NETCOREAPP3_0
        [Fact]
        public void When_subject_throws_the_expected_exact_exception_through_ValueTask_it_should_succeed()
        {
            //-----------------------------------------------------------------------------------------------------------
            // Arrange
            //-----------------------------------------------------------------------------------------------------------
            var asyncObject = new AsyncClass();

            //-----------------------------------------------------------------------------------------------------------
            // Act / Assert
            //-----------------------------------------------------------------------------------------------------------
            asyncObject
                .Awaiting(x => x.ThrowAsyncValueTask<ArgumentNullException>())
                .Should().ThrowExactly<ArgumentNullException>();
        }
#endif

        [Fact]
        public void When_async_method_throws_expected_exception_it_should_succeed()
        {
            // Arrange
            var asyncObject = new AsyncClass();

            // Act
            Action action = () => asyncObject
                .Awaiting(x => x.ThrowAsync<ArgumentException>())
                .Should().Throw<ArgumentException>();

            // Assert
            action.Should().NotThrow();
        }

#if NETCOREAPP2_1 || NETCOREAPP3_0
        [Fact]
        public void When_async_method_throws_expected_exception__through_ValueTask_it_should_succeed()
        {
            //-----------------------------------------------------------------------------------------------------------
            // Arrange
            //-----------------------------------------------------------------------------------------------------------
            var asyncObject = new AsyncClass();

            //-----------------------------------------------------------------------------------------------------------
            // Act
            //-----------------------------------------------------------------------------------------------------------
            Action action = () => asyncObject
                .Awaiting(x => x.ThrowAsyncValueTask<ArgumentException>())
                .Should().Throw<ArgumentException>();

            //-----------------------------------------------------------------------------------------------------------
            // Assert
            //-----------------------------------------------------------------------------------------------------------
            action.Should().NotThrow();
        }
#endif

        [Fact]
        public void When_subject_is_null_it_should_be_null()
        {
            // Arrange
            Func<Task> subject = null;

            // Act
            Action action = () => subject.Should().NotThrow();

            // Assert
            action.Should().Throw<XunitException>()
                .WithMessage("*found <null>*");
        }

        [Fact]
        public async Task When_async_method_throws_async_expected_exception_it_should_succeed()
        {
            // Arrange
            var asyncObject = new AsyncClass();

            // Act
            Func<Task> action = () => asyncObject.ThrowAsync<ArgumentException>();

            // Assert
            await action.Should().ThrowAsync<ArgumentException>();
        }

        [Fact]
        public void When_async_method_does_not_throw_expected_exception_it_should_fail()
        {
            // Arrange
            var asyncObject = new AsyncClass();

            // Act
            Action action = () => asyncObject
                .Awaiting(x => x.SucceedAsync())
                .Should().Throw<InvalidOperationException>("because {0} should do that", "IFoo.Do");

            // Assert
            action.Should().Throw<XunitException>()
                .WithMessage("Expected a <System.InvalidOperationException> to be thrown because IFoo.Do should do that, but no exception was thrown.");
        }

#if NETCOREAPP2_1 || NETCOREAPP3_0
        [Fact]
        public void When_async_method_does_not_throw_expected_exception_through_ValueTask_it_should_fail()
        {
            //-----------------------------------------------------------------------------------------------------------
            // Arrange
            //-----------------------------------------------------------------------------------------------------------
            var asyncObject = new AsyncClass();

            //-----------------------------------------------------------------------------------------------------------
            // Act
            //-----------------------------------------------------------------------------------------------------------
            Action action = () => asyncObject
                .Awaiting(x => x.SucceedAsyncValueTask())
                .Should().Throw<InvalidOperationException>("because {0} should do that", "IFoo.Do");

            //-----------------------------------------------------------------------------------------------------------
            // Assert
            //-----------------------------------------------------------------------------------------------------------
            action.Should().Throw<XunitException>()
                .WithMessage("Expected a <System.InvalidOperationException> to be thrown because IFoo.Do should do that, but no exception was thrown.");
        }
#endif

        [Fact]
        public void When_async_method_throws_unexpected_exception_it_should_fail()
        {
            // Arrange
            var asyncObject = new AsyncClass();

            // Act
            Action action = () => asyncObject
                .Awaiting(x => x.ThrowAsync<ArgumentException>())
                .Should().Throw<InvalidOperationException>("because {0} should do that", "IFoo.Do");

            // Assert
            action.Should().Throw<XunitException>()
                .WithMessage("Expected a <System.InvalidOperationException> to be thrown because IFoo.Do should do that, but found <System.ArgumentException>*");
        }

#if NETCOREAPP2_1 || NETCOREAPP3_0
        [Fact]
        public void When_async_method_throws_unexpected_exception_through_ValueTask_it_should_fail()
        {
            //-----------------------------------------------------------------------------------------------------------
            // Arrange
            //-----------------------------------------------------------------------------------------------------------
            var asyncObject = new AsyncClass();

            //-----------------------------------------------------------------------------------------------------------
            // Act
            //-----------------------------------------------------------------------------------------------------------
            Action action = () => asyncObject
                .Awaiting(x => x.ThrowAsyncValueTask<ArgumentException>())
                .Should().Throw<InvalidOperationException>("because {0} should do that", "IFoo.Do");

            //-----------------------------------------------------------------------------------------------------------
            // Assert
            //-----------------------------------------------------------------------------------------------------------
            action.Should().Throw<XunitException>()
                .WithMessage("Expected a <System.InvalidOperationException> to be thrown because IFoo.Do should do that, but found <System.ArgumentException>*");
        }
#endif

        [Fact]
        public void When_async_method_does_not_throw_exception_and_that_was_expected_it_should_succeed()
        {
            // Arrange
            var asyncObject = new AsyncClass();

            // Act
            Action action = () => asyncObject
                .Awaiting(x => x.SucceedAsync())
                .Should().NotThrow();

            // Assert
            action.Should().NotThrow();
        }

#if NETCOREAPP2_1 || NETCOREAPP3_0
        [Fact]
        public void When_async_method_does_not_throw_exception_through_ValueTask_and_that_was_expected_it_should_succeed()
        {
            //-----------------------------------------------------------------------------------------------------------
            // Arrange
            //-----------------------------------------------------------------------------------------------------------
            var asyncObject = new AsyncClass();

            //-----------------------------------------------------------------------------------------------------------
            // Act
            //-----------------------------------------------------------------------------------------------------------
            Action action = () => asyncObject
                .Awaiting(x => x.SucceedAsyncValueTask())
                .Should().NotThrow();

            //-----------------------------------------------------------------------------------------------------------
            // Assert
            //-----------------------------------------------------------------------------------------------------------
            action.Should().NotThrow();
        }
#endif

        [Fact]
        public async Task When_async_method_does_not_throw_async_exception_and_that_was_expected_it_should_succeed()
        {
            // Arrange
            var asyncObject = new AsyncClass();

            // Act
            Func<Task> action = () => asyncObject.SucceedAsync();

            // Assert
            await action.Should().NotThrowAsync();
        }

        [Fact]
        public async Task When_subject_throws_subclass_of_expected_async_exception_it_should_succeed()
        {
            // Arrange
            var asyncObject = new AsyncClass();

            // Act
            Func<Task> action = () => asyncObject.ThrowAsync<ArgumentNullException>();

            // Assert
            await action.Should().ThrowAsync<ArgumentException>("because {0} should do that", "IFoo.Do");
        }

        [Fact]
        public void When_function_of_task_int_in_async_method_throws_the_expected_exception_it_should_succeed()
        {
            // Arrange
            var asyncObject = new AsyncClass();
            Func<Task<int>> f = () => asyncObject.ThrowTaskIntAsync<ArgumentNullException>(true);

            // Act / Assert
            f.Should().Throw<ArgumentNullException>();
        }

        [Fact]
        public void When_function_of_task_int_in_async_method_throws_not_excepted_exception_it_should_succeed()
        {
            // Arrange
            var asyncObject = new AsyncClass();
            Func<Task<int>> f = () => asyncObject.ThrowTaskIntAsync<InvalidOperationException>(true);

            // Act / Assert
            f.Should().NotThrow<ArgumentNullException>();
        }

        [Fact]
        public void When_subject_is_null_when_expecting_an_exact_exception_it_should_throw()
        {
            // Arrange
            Func<Task> action = null;

            // Act
            Func<Task> testAction = () => action.Should().ThrowExactlyAsync<ArgumentException>(
                "because we want to test the failure {0}", "message");

            // Assert
            testAction.Should().Throw<XunitException>()
                .WithMessage("*because we want to test the failure message*found <null>*");
        }

        [Fact]
        public async Task When_subject_throws_subclass_of_expected_async_exact_exception_it_should_throw()
        {
            // Arrange
            var asyncObject = new AsyncClass();

            // Act
            Func<Task> action = () => asyncObject.ThrowAsync<ArgumentNullException>();
            Func<Task> testAction = () => action.Should().ThrowExactlyAsync<ArgumentException>("ABCDE");

            // Assert
            await testAction.Should().ThrowAsync<XunitException>()
                .WithMessage("*ArgumentException*ABCDE*ArgumentNullException*");
        }

        [Fact]
        public async Task When_subject_throws_aggregate_exception_instead_of_exact_exception_it_should_throw()
        {
            // Arrange
            var asyncObject = new AsyncClass();

            // Act
            Func<Task> action = () => asyncObject.ThrowAggregateExceptionAsync<ArgumentException>();
            Func<Task> testAction = () => action.Should().ThrowExactlyAsync<ArgumentException>("ABCDE");

            // Assert
            await testAction.Should().ThrowAsync<XunitException>()
                .WithMessage("*ArgumentException*ABCDE*AggregateException*");
        }

        [Fact]
        public async Task When_subject_throws_expected_async_exact_exception_it_should_succeed()
        {
            // Arrange
            var asyncObject = new AsyncClass();

            // Act
            Func<Task> action = () => asyncObject.ThrowAsync<ArgumentException>();

            // Assert
            await action.Should().ThrowExactlyAsync<ArgumentException>("because {0} should do that", "IFoo.Do");
        }

        [Fact]
        public void When_async_method_throws_exception_and_no_exception_was_expected_it_should_fail()
        {
            // Arrange
            var asyncObject = new AsyncClass();

            // Act
            Action action = () => asyncObject
                .Awaiting(x => x.ThrowAsync<ArgumentException>())
                .Should().NotThrow();

            // Assert
            action.Should().Throw<XunitException>()
                .WithMessage("Did not expect any exception, but found System.ArgumentException*");
        }

#if NETCOREAPP2_1 || NETCOREAPP3_0
        [Fact]
        public void When_async_method_throws_exception_through_ValueTask_and_no_exception_was_expected_it_should_fail()
        {
            //-----------------------------------------------------------------------------------------------------------
            // Arrange
            //-----------------------------------------------------------------------------------------------------------
            var asyncObject = new AsyncClass();

            //-----------------------------------------------------------------------------------------------------------
            // Act
            //-----------------------------------------------------------------------------------------------------------
            Action action = () => asyncObject
                .Awaiting(x => x.ThrowAsyncValueTask<ArgumentException>())
                .Should().NotThrow();

            //-----------------------------------------------------------------------------------------------------------
            // Assert
            //-----------------------------------------------------------------------------------------------------------
            action.Should().Throw<XunitException>()
                .WithMessage("Did not expect any exception, but found System.ArgumentException*");
        }
#endif

        [Fact]
        public void When_async_method_throws_exception_and_expected_not_to_throw_another_one_it_should_succeed()
        {
            // Arrange
            var asyncObject = new AsyncClass();

            // Act
            Action action = () => asyncObject
                .Awaiting(x => x.ThrowAsync<ArgumentException>())
                .Should().NotThrow<InvalidOperationException>();

            // Assert
            action.Should().NotThrow();
        }

#if NETCOREAPP2_1 || NETCOREAPP3_0
        [Fact]
        public void When_async_method_throws_exception_through_ValueTask_and_expected_not_to_throw_another_one_it_should_succeed()
        {
            //-----------------------------------------------------------------------------------------------------------
            // Arrange
            //-----------------------------------------------------------------------------------------------------------
            var asyncObject = new AsyncClass();

            //-----------------------------------------------------------------------------------------------------------
            // Act
            //-----------------------------------------------------------------------------------------------------------
            Action action = () => asyncObject
                .Awaiting(x => x.ThrowAsyncValueTask<ArgumentException>())
                .Should().NotThrow<InvalidOperationException>();

            //-----------------------------------------------------------------------------------------------------------
            // Assert
            //-----------------------------------------------------------------------------------------------------------
            action.Should().NotThrow();
        }
#endif

        [Fact]
        public async Task When_async_method_throws_exception_and_expected_not_to_throw_async_another_one_it_should_succeed()
        {
            // Arrange
            var asyncObject = new AsyncClass();

            // Act
            Func<Task> action = () => asyncObject.ThrowAsync<ArgumentException>();

            // Assert
            await action.Should().NotThrowAsync<InvalidOperationException>();
        }

        [Fact]
        public void When_async_method_succeeds_and_expected_not_to_throw_particular_exception_it_should_succeed()
        {
            // Arrange
            var asyncObject = new AsyncClass();

            // Act
            Action action = () => asyncObject
                .Awaiting(x => asyncObject.SucceedAsync())
                .Should().NotThrow<InvalidOperationException>();

            // Assert
            action.Should().NotThrow();
        }

#if NETCOREAPP2_1 || NETCOREAPP3_0
        [Fact]
        public void When_async_method_succeeds_and_expected_not_to_throw_particular_exception_through_ValueTask_it_should_succeed()
        {
            //-----------------------------------------------------------------------------------------------------------
            // Arrange
            //-----------------------------------------------------------------------------------------------------------
            var asyncObject = new AsyncClass();

            //-----------------------------------------------------------------------------------------------------------
            // Act
            //-----------------------------------------------------------------------------------------------------------
            Action action = () => asyncObject
                .Awaiting(x => asyncObject.SucceedAsyncValueTask())
                .Should().NotThrow<InvalidOperationException>();

            //-----------------------------------------------------------------------------------------------------------
            // Assert
            //-----------------------------------------------------------------------------------------------------------
            action.Should().NotThrow();
        }
#endif

        [Fact]//
        public void When_async_method_throws_exception_expected_not_to_be_thrown_it_should_fail()
        {
            // Arrange
            var asyncObject = new AsyncClass();

            // Act
            Action action = () => asyncObject
                .Awaiting(x => x.ThrowAsync<ArgumentException>())
                .Should().NotThrow<ArgumentException>();

            // Assert
            action.Should().Throw<XunitException>()
                .WithMessage("Did not expect System.ArgumentException, but found*");
        }

#if NETCOREAPP2_1 || NETCOREAPP3_0
        [Fact]//
        public void When_async_method_throws_exception_expected_through_ValueTask_not_to_be_thrown_it_should_fail()
        {
            //-----------------------------------------------------------------------------------------------------------
            // Arrange
            //-----------------------------------------------------------------------------------------------------------
            var asyncObject = new AsyncClass();

            //-----------------------------------------------------------------------------------------------------------
            // Act
            //-----------------------------------------------------------------------------------------------------------
            Action action = () => asyncObject
                .Awaiting(x => x.ThrowAsyncValueTask<ArgumentException>())
                .Should().NotThrow<ArgumentException>();

            //-----------------------------------------------------------------------------------------------------------
            // Assert
            //-----------------------------------------------------------------------------------------------------------
            action.Should().Throw<XunitException>()
                .WithMessage("Did not expect System.ArgumentException, but found*");
        }
#endif

        [Fact]
        public void When_async_method_of_T_succeeds_and_expected_not_to_throw_particular_exception_it_should_succeed()
        {
            // Arrange
            var asyncObject = new AsyncClass();

            // Act
            Action action = () => asyncObject
                .Awaiting(x => asyncObject.ReturnTaskInt())
                .Should().NotThrow<InvalidOperationException>();

            // Assert
            action.Should().NotThrow();
        }

#if NETCOREAPP2_0 || NETCOREAPP2_1 || NETCOREAPP3_0
        [Fact]
        public void When_ValueTask_async_method_of_T_succeeds_and_expected_not_to_throw_particular_exception_it_should_succeed()
        {
            //-----------------------------------------------------------------------------------------------------------
            // Arrange
            //-----------------------------------------------------------------------------------------------------------
            var asyncObject = new AsyncClass();

            //-----------------------------------------------------------------------------------------------------------
            // Act
            //-----------------------------------------------------------------------------------------------------------
            Action action = () => asyncObject
                .Awaiting(x => asyncObject.ReturnValueTaskInt())
                .Should().NotThrow<InvalidOperationException>();

            //-----------------------------------------------------------------------------------------------------------
            // Assert
            //-----------------------------------------------------------------------------------------------------------
            action.Should().NotThrow();
        }
#endif

        [Fact]
        public void When_async_method_of_T_throws_exception_expected_not_to_be_thrown_it_should_fail()
        {
            // Arrange
            var asyncObject = new AsyncClass();

            // Act
            Action action = () => asyncObject
                .Awaiting(x => x.ThrowTaskIntAsync<ArgumentException>(true))
                .Should().NotThrow<ArgumentException>();

            // Assert
            action.Should().Throw<XunitException>()
                .WithMessage("Did not expect System.ArgumentException, but found System.ArgumentException*");
        }

#if NETCOREAPP2_0 || NETCOREAPP2_1 || NETCOREAPP3_0
        [Fact]
        public void When_ValueTask_async_method_of_T_throws_exception_expected_not_to_be_thrown_it_should_fail()
        {
            //-----------------------------------------------------------------------------------------------------------
            // Arrange
            //-----------------------------------------------------------------------------------------------------------
            var asyncObject = new AsyncClass();

            //-----------------------------------------------------------------------------------------------------------
            // Act
            //-----------------------------------------------------------------------------------------------------------
            Action action = () => asyncObject
                .Awaiting(x => x.ThrowValueTaskIntAsync<ArgumentException>(true))
                .Should().NotThrow<ArgumentException>();

            //-----------------------------------------------------------------------------------------------------------
            // Assert
            //-----------------------------------------------------------------------------------------------------------
            action.Should().Throw<XunitException>()
                .WithMessage("Did not expect System.ArgumentException, but found System.ArgumentException*");
        }
#endif

        [Fact]
        public void When_async_method_throws_the_expected_inner_exception_it_should_succeed()
        {
            // Arrange
            Func<Task> task = async () =>
            {
                await Task.Delay(100);
                throw new AggregateException(new InvalidOperationException());
            };

            // Act
            Action action = () => task
                .Should().Throw<AggregateException>()
                .WithInnerException<InvalidOperationException>();

            // Assert
            action.Should().NotThrow();
        }

        [Fact]
        public void When_async_method_throws_aggregate_exception_containing_expected_exception_it_should_succeed()
        {
            // Arrange
            Func<Task> task = async () =>
            {
                await Task.Delay(100);
                throw new AggregateException(new InvalidOperationException());
            };

            // Act
            Action action = () => task
                .Should().Throw<InvalidOperationException>();

            // Assert
            action.Should().NotThrow();
        }

        [Fact]
        public void When_async_method_throws_the_expected_exception_it_should_succeed()
        {
            // Arrange
            Func<Task> task = async () =>
            {
                await Task.Delay(100);
                throw new InvalidOperationException();
            };

            // Act
            Action action = () => task
                .Should().Throw<InvalidOperationException>();

            // Assert
            action.Should().NotThrow();
        }

        [Fact]
        public void When_async_method_does_not_throw_the_expected_inner_exception_it_should_fail()
        {
            // Arrange
            Func<Task> task = async () =>
            {
                await Task.Delay(100);
                throw new AggregateException(new ArgumentException());
            };

            // Act
            Action action = () => task
                .Should().Throw<AggregateException>()
                .WithInnerException<InvalidOperationException>();

            // Assert
            action.Should().Throw<XunitException>().WithMessage("*InvalidOperation*Argument*");
        }

        [Fact]
        public void When_async_method_does_not_throw_the_expected_exception_it_should_fail()
        {
            // Arrange
            Func<Task> task = async () =>
            {
                await Task.Delay(100);
                throw new ArgumentException();
            };

            // Act
            Action action = () => task
                .Should().Throw<InvalidOperationException>();

            // Assert
            action.Should().Throw<XunitException>().WithMessage("*InvalidOperation*Argument*");
        }

        [Fact]
        public void When_asserting_async_void_method_should_throw_it_should_fail()
        {
            // Arrange
            var asyncObject = new AsyncClass();
            Action asyncVoidMethod = async () => await asyncObject.IncompleteTask();

            // Act
            Action action = () => asyncVoidMethod.Should().Throw<ArgumentException>();

            // Assert
            action.Should().Throw<InvalidOperationException>("*async*void*");
        }

        [Fact]
        public void When_asserting_async_void_method_should_throw_exactly_it_should_fail()
        {
            // Arrange
            var asyncObject = new AsyncClass();
            Action asyncVoidMethod = async () => await asyncObject.IncompleteTask();

            // Act
            Action action = () => asyncVoidMethod.Should().ThrowExactly<ArgumentException>();

            // Assert
            action.Should().Throw<InvalidOperationException>("*async*void*");
        }

        [Fact]
        public void When_asserting_async_void_method_should_not_throw_it_should_fail()
        {
            // Arrange
            var asyncObject = new AsyncClass();
            Action asyncVoidMethod = async () => await asyncObject.IncompleteTask();

            // Act
            Action action = () => asyncVoidMethod.Should().NotThrow();

            // Assert
            action.Should().Throw<InvalidOperationException>("*async*void*");
        }

        [Fact]
        public void When_asserting_async_void_method_should_not_throw_specific_exception_it_should_fail()
        {
            // Arrange
            var asyncObject = new AsyncClass();
            Action asyncVoidMethod = async () => await asyncObject.IncompleteTask();

            // Act
            Action action = () => asyncVoidMethod.Should().NotThrow<ArgumentException>();

            // Assert
            action.Should().Throw<InvalidOperationException>("*async*void*");
        }

        #region NotThrowAfter

        [Fact]
        public void When_wait_time_is_negative_for_async_func_executed_with_wait_it_should_throw()
        {
            // Arrange
            var waitTime = -1.Milliseconds();
            var pollInterval = 10.Milliseconds();

            var asyncObject = new AsyncClass();
            Func<Task> someFunc = () => asyncObject.SucceedAsync();

            // Act
            Action act = () => someFunc.Should().NotThrowAfter(waitTime, pollInterval);

            // Assert
            act.Should().Throw<ArgumentOutOfRangeException>()
                .WithMessage("* value of waitTime must be non-negative*");
        }

        [Fact]
        public void When_poll_interval_is_negative_for_async_func_executed_with_wait_it_should_throw()
        {
            // Arrange
            var waitTime = 10.Milliseconds();
            var pollInterval = -1.Milliseconds();

            var asyncObject = new AsyncClass();
            Func<Task> someFunc = () => asyncObject.SucceedAsync();

            // Act
            Action act = () => someFunc.Should().NotThrowAfter(waitTime, pollInterval);

            // Assert
            act.Should().Throw<ArgumentOutOfRangeException>()
                .WithMessage("* value of pollInterval must be non-negative*");
        }

        [Fact]
        public void
            When_no_exception_should_be_thrown_for_async_func_executed_with_wait_after_wait_time_but_it_was_it_should_throw()
        {
            // Arrange
            var waitTime = 2.Seconds();
            var pollInterval = 10.Milliseconds();

            var clock = new FakeClock();
            var timer = clock.StartTimer();
            clock.Delay(waitTime);

            Func<Task> throwLongerThanWaitTime = async () =>
            {
                if (timer.Elapsed <= waitTime.Multiply(1.5))
                {
                    throw new ArgumentException("An exception was forced");
                }

                await Task.Delay(0);
            };

            // Act
            Action action = () => throwLongerThanWaitTime.Should(clock)
                .NotThrowAfter(waitTime, pollInterval, "we passed valid arguments");

            // Assert
            action.Should().Throw<XunitException>()
                .WithMessage("Did not expect any exceptions after 2s because we passed valid arguments*");
        }

        [Fact]
        public void When_no_exception_should_be_thrown_for_async_func_executed_with_wait_after_wait_time_and_none_was_it_should_not_throw()
        {
            // Arrange
            var waitTime = 6.Seconds();
            var pollInterval = 10.Milliseconds();

            var clock = new FakeClock();
            var timer = clock.StartTimer();
            clock.Delay(waitTime);

            Func<Task> throwShorterThanWaitTime = async () =>
            {
                if (timer.Elapsed <= waitTime.Divide(12))
                {
                    throw new ArgumentException("An exception was forced");
                }
                await Task.Delay(0);
            };

            // Act
            Action act = () => throwShorterThanWaitTime.Should(clock).NotThrowAfter(waitTime, pollInterval);

            // Assert
            act.Should().NotThrow();
        }

        #endregion

        #region NotThrowAfterAsync
        [Fact]
        public void When_subject_is_null_for_async_func_it_should_throw()
        {
            // Arrange
            var waitTime = 0.Milliseconds();
            var pollInterval = 0.Milliseconds();
            Func<Task> action = null;

            // Act
            Func<Task> testAction = () => action.Should().NotThrowAfterAsync(
                waitTime, pollInterval, "because we want to test the failure {0}", "message");

            // Assert
            testAction.Should().Throw<XunitException>()
                .WithMessage("*because we want to test the failure message*found <null>*");
        }

        [Fact]
        public void When_wait_time_is_negative_for_async_func_it_should_throw()
        {
            // Arrange
            var waitTime = -1.Milliseconds();
            var pollInterval = 10.Milliseconds();

            var asyncObject = new AsyncClass();
            Func<Task> someFunc = () => asyncObject.SucceedAsync();

            // Act
            Func<Task> act = () => someFunc.Should().NotThrowAfterAsync(waitTime, pollInterval);

            // Assert
            act.Should().Throw<ArgumentOutOfRangeException>()
                .WithMessage("* value of waitTime must be non-negative*");
        }

        [Fact]
        public void When_poll_interval_is_negative_for_async_func_it_should_throw()
        {
            // Arrange
            var waitTime = 10.Milliseconds();
            var pollInterval = -1.Milliseconds();

            var asyncObject = new AsyncClass();
            Func<Task> someFunc = () => asyncObject.SucceedAsync();

            // Act
            Func<Task> act = () => someFunc.Should().NotThrowAfterAsync(waitTime, pollInterval);

            // Assert
            act.Should().Throw<ArgumentOutOfRangeException>()
                .WithMessage("* value of pollInterval must be non-negative*");
        }

        [Fact]
        public void When_no_exception_should_be_thrown_for_null_async_func_after_wait_time_it_should_throw()
        {
            // Arrange
            var waitTime = 2.Seconds();
            var pollInterval = 10.Milliseconds();

            Func<Task> func = null;

            // Act
            Func<Task> action = () => func.Should()
                .NotThrowAfterAsync(waitTime, pollInterval, "we passed valid arguments");

            // Assert
            action.Should().Throw<XunitException>()
                .WithMessage("*but found <null>*");
        }

        [Fact]
        public void When_no_exception_should_be_thrown_for_async_func_after_wait_time_but_it_was_it_should_throw()
        {
            // Arrange
            var waitTime = 2.Seconds();
            var pollInterval = 10.Milliseconds();

            var clock = new FakeClock();
            var timer = clock.StartTimer();
            clock.Delay(waitTime);
            clock.CompletesBeforeTimeout();

            Func<Task> throwLongerThanWaitTime = async () =>
            {
                if (timer.Elapsed <= waitTime.Multiply(1.5))
                {
                    throw new ArgumentException("An exception was forced");
                }

                await Task.Delay(0);
            };

            // Act
            Func<Task> action = () => throwLongerThanWaitTime.Should(clock)
                .NotThrowAfterAsync(waitTime, pollInterval, "we passed valid arguments");

            // Assert
            action.Should().Throw<XunitException>()
                .WithMessage("Did not expect any exceptions after 2s because we passed valid arguments*");
        }

        [Fact]
        public void When_no_exception_should_be_thrown_for_async_func_after_wait_time_and_none_was_it_should_not_throw()
        {
            // Arrange
            var waitTime = 6.Seconds();
            var pollInterval = 10.Milliseconds();

            var clock = new FakeClock();
            var timer = clock.StartTimer();
            clock.Delay(waitTime);

            Func<Task> throwShorterThanWaitTime = async () =>
            {
                if (timer.Elapsed <= waitTime.Divide(12))
                {
                    throw new ArgumentException("An exception was forced");
                }

                await Task.Delay(0);
            };

            // Act
            Func<Task> act = () => throwShorterThanWaitTime.Should(clock).NotThrowAfterAsync(waitTime, pollInterval);

            // Assert
            act.Should().NotThrow();
        }

        #endregion
    }

    internal class AsyncClass
    {
        public async Task ThrowAsync<TException>()
            where TException : Exception, new()
        {
            await Task.Yield();
            throw new TException();
        }

#if NETCOREAPP2_1 || NETCOREAPP3_0
        public async ValueTask ThrowAsyncValueTask<TException>()
            where TException : Exception, new()
        {
            await Task.Yield();
            throw new TException();
        }
#endif

        public async Task ThrowAggregateExceptionAsync<TException>() where TException : Exception, new()
        {
            await Task.Yield();
            throw new AggregateException(new TException());
        }

#if NETCOREAPP2_1 || NETCOREAPP3_0
        public async ValueTask ThrowAggregateExceptionAsyncValueTask<TException>() where TException : Exception, new()
        {
            await Task.Yield();
            throw new AggregateException(new TException());
        }
#endif

        public async Task SucceedAsync()
        {
            await Task.FromResult(0);
        }

#if NETCOREAPP2_1 || NETCOREAPP3_0
        public async ValueTask SucceedAsyncValueTask()
        {
            await Task.FromResult(0);
        }
#endif

        public Task<int> ReturnTaskInt()
        {
            return Task.FromResult(0);
        }

#if NETCOREAPP2_0 || NETCOREAPP2_1 || NETCOREAPP3_0
        public ValueTask<int> ReturnValueTaskInt()
        {
            return new ValueTask<int>(0);
        }
#endif

        public Task IncompleteTask()
        {
            return new TaskCompletionSource<bool>().Task;
        }

        public async Task<int> ThrowTaskIntAsync<TException>(bool throwException)
            where TException : Exception, new()
        {
            await Task.Yield();

            if (throwException)
            {
                throw new TException();
            }

            return 123;
        }

#if NETCOREAPP2_0 || NETCOREAPP2_1 || NETCOREAPP3_0
        public async ValueTask<int> ThrowValueTaskIntAsync<TException>(bool throwException)
            where TException : Exception, new()
        {
            await Task.Yield();

            if (throwException)
            {
                throw new TException();
            }

            return 123;
        }
#endif
    }
}
